# 1.含义

async 函数，使得异步操作变得更加方便。

async 函数 是 Generator 函数的语法糖。

前文有一个 Generator 函数，依次读取两个文件。

```javascript
const fs = require('fs');

const readFile = function (fileName) {
  return new Promise(function (resolve, reject) {
    fs.readFile(fileName, function(error, data) {
      if (error) return reject(error);
      resolve(data);
    });
  });
};

const gen = function* () {
  const f1 = yield readFile('/etc/fstab');
  const f2 = yield readFile('/etc/shells');
  console.log(f1.toString());
  console.log(f2.toString());
};
```

上面代码的函数gen可以写成async函数，就是下面这样。

```javascript
const asyncReadFile = async function () {
  const f1 = await readFile('/etc/fstab');
  const f2 = await readFile('/etc/shells');
  console.log(f1.toString());
  console.log(f2.toString());
};
```

async函数就是将 Generator 函数的星号（*）替换成async，将yield替换成await

async函数对 Generator 函数的改进，体现在以下四点。

（1）内置执行器。

Generator 函数的执行必须靠执行器，所以才有了co模块，而async函数自带执行器。也就是说，async函数的执行，与普通函数一模一样，只要一行。

```javascript
asyncReadFile();
```

上面的代码调用了asyncReadFile函数，然后它就会自动执行，输出最后结果。这完全不像 Generator 函数，需要调用next方法，或者用co模块，才能真正执行，得到最后结果。

（2）更好的语义。

async和await，比起星号和yield，语义更清楚了。async表示函数里有异步操作，await表示紧跟在后面的表达式需要等待结果。

（3）更广的适用性。

co模块约定，yield命令后面只能是 Thunk 函数或 Promise 对象，而async函数的await命令后面，可以是 Promise 对象和原始类型的值（数值、字符串和布尔值，但这时会自动转成立即 resolved 的 Promise 对象）。

（4）返回值是 Promise。

async函数的返回值是 Promise 对象，这比 Generator 函数的返回值是 Iterator 对象方便多了。你可以用then方法指定下一步的操作。

进一步说，async函数完全可以看作多个异步操作，包装成的一个 Promise 对象，而await命令就是内部then命令的语法糖。


# 2. 基本用法
async函数返回一个 Promise 对象，可以使用then方法添加回调函数。当函数执行的时候，一旦遇到await就会先返回，等到异步操作完成，再接着执行函数体内后面的语句。

```javascript
async function getStockPriceByName(name) {
  const symbol = await getStockSymbol(name);
  const stockPrice = await getStockPrice(symbol);
  return stockPrice;
}

getStockPriceByName('goog').then(function (result) {
  console.log(result);
});
```

上面代码是一个获取股票报价的函数，函数前面的async关键字，表明该函数内部有异步操作。调用该函数时，会立即返回一个Promise对象。

下面是另一个例子，指定多少毫秒后输出一个值。

```javascript
function timeout(ms) {
  return new Promise((resolve) => {
    setTimeout(resolve, ms);
  });
}

async function asyncPrint(value, ms) {
  await timeout(ms);
  console.log(value);
}

asyncPrint('hello world', 50);
```

上面代码指定 50 毫秒以后，输出hello world。

由于async函数返回的是 Promise 对象，可以作为await命令的参数。所以，上面的例子也可以写成下面的形式。

```javascript
async function timeout(ms) {
  await new Promise((resolve) => {
    setTimeout(resolve, ms);
  });
}

async function asyncPrint(value, ms) {
  await timeout(ms);
  console.log(value);
}

asyncPrint('hello world', 50);
```

async 函数有多种使用形式。

```javascript
// 函数声明
async function foo() {}

// 函数表达式
const foo = async function () {};

// 对象的方法
let obj = { async foo() {} };
obj.foo().then(...)

// Class 的方法
class Storage {
  constructor() {
    this.cachePromise = caches.open('avatars');
  }

  async getAvatar(name) {
    const cache = await this.cachePromise;
    return cache.match(`/avatars/${name}.jpg`);
  }
}

const storage = new Storage();
storage.getAvatar('jake').then(…);

// 箭头函数
const foo = async () => {};
```

# 3.语法
async函数的语法规则总体上比较简单，难点是错误处理机制。

## 返回 Promise 对象

### async函数返回一个 Promise 对象。

### async函数内部return语句返回的值，会成为then方法回调函数的参数。

```javascript
async function f() {
  return 'hello world';
}

f().then(v => console.log(v))
// "hello world"
```

### async函数内部抛出错误，会导致返回的 Promise 对象变为reject状态。抛出的错误对象会被catch方法回调函数接收到。

```javascript
async function f() {
  throw new Error('出错了');
}

f().then(
  v => console.log('resolve', v),
  e => console.log('reject', e)
)
//reject Error: 出错了
```

## Promise 对象的状态变化

### async函数返回的 Promise 对象，必须等到内部所有await命令后面的 Promise 对象执行完，才会发生状态改变，除非遇到return语句或者抛出错误。也就是说，只有async函数内部的异步操作执行完，才会执行then方法指定的回调函数。

```javascript
async function getTitle(url) {
  let response = await fetch(url);
  let html = await response.text();
  return html.match(/<title>([\s\S]+)<\/title>/i)[1];
}
getTitle('https://tc39.github.io/ecma262/').then(console.log)
// "ECMAScript 2017 Language Specification"
```

上面代码中，函数getTitle内部有三个操作：抓取网页、取出文本、匹配页面标题。只有这三个操作全部完成，才会执行then方法里面的console.log。

## await 命令

### 正常情况下，await命令后面是一个 Promise 对象，返回该对象的结果。如果不是 Promise 对象，就直接返回对应的值。

```javascript
async function f() {
  // 等同于
  // return 123;
  return await 123;
}

f().then(v => console.log(v))
// 123
```

### 另一种情况是，await命令后面是一个thenable对象（即定义了then方法的对象），那么await会将其等同于 Promise 对象。

```javascript
class Sleep {
  constructor(timeout) {
    this.timeout = timeout;
  }
  then(resolve, reject) {
    const startTime = Date.now();
    setTimeout(
      () => resolve(Date.now() - startTime),
      this.timeout
    );
  }
}

(async () => {
  const sleepTime = await new Sleep(1000);
  console.log(sleepTime);
})();
// 1000
```

上面代码中，await命令后面是一个Sleep对象的实例。这个实例不是 Promise 对象，但是因为定义了then方法，await会将其视为Promise处理。

这个例子还演示了如何实现休眠效果。JavaScript 一直没有休眠的语法，但是借助await命令就可以让程序停顿指定的时间。下面给出了一个简化的sleep实现。

```javascript
function sleep(interval) {
  return new Promise(resolve => {
    setTimeout(resolve, interval);
  })
}

// 用法
async function one2FiveInAsync() {
  for(let i = 1; i <= 5; i++) {
    console.log(i);
    await sleep(1000);
  }
}

one2FiveInAsync();
```


### 任何一个await语句后面的 Promise 对象变为reject状态，那么整个async函数都会中断执行。
### await命令后面的 Promise 对象如果变为reject状态，则reject的参数会被catch方法的回调函数接收到。

```javascript
async function f() {
  await Promise.reject('出错了');
}

f()
.then(v => console.log(v))
.catch(e => console.log(e))
// 出错了
```

```javascript
async function f() {
  await Promise.reject('出错了');
  await Promise.resolve('hello world'); // 不会执行
}
```

### 将第一个await放在try...catch结构里面，这样不管这个异步操作是否成功，第二个await都会执行。

```javascript
async function f() {
  try {
    await Promise.reject('出错了');
  } catch(e) {
  }
  return await Promise.resolve('hello world');
}

f()
.then(v => console.log(v))
// hello world
```

### 将第一个await后面的 Promise 对象再跟一个catch方法，处理前面可能出现的错误，第二个await都会执行。

```javascript
async function f() {
  await Promise.reject('出错了')
    .catch(e => console.log(e));
  return await Promise.resolve('hello world');
}

f()
.then(v => console.log(v))
// 出错了
// hello world
```

## 错误处理

### 如果await后面的异步操作出错，那么等同于async函数返回的 Promise 对象被reject。

```javascript
async function f() {
  await new Promise(function (resolve, reject) {
    throw new Error('出错了');
  });
}

f()
.then(v => console.log(v))
.catch(e => console.log(e))
// Error：出错了
```

上面代码中，async函数f执行后，await后面的 Promise 对象会抛出一个错误对象，导致catch方法的回调函数被调用，它的参数就是抛出的错误对象。具体的执行机制，可以参考后文的“async 函数的实现原理”。

### 防止出错的方法，也是将其放在try...catch代码块之中。

```javascript
async function f() {
  try {
    await new Promise(function (resolve, reject) {
      throw new Error('出错了');
    });
  } catch(e) {
  }
  return await('hello world');
}
```

### 如果有多个await命令，可以统一放在try...catch结构中。

```javascript
async function main() {
  try {
    const val1 = await firstStep();
    const val2 = await secondStep(val1);
    const val3 = await thirdStep(val1, val2);

    console.log('Final: ', val3);
  }
  catch (err) {
    console.error(err);
  }
}
```

下面的例子使用try...catch结构，实现多次重复尝试。

```javascript
const superagent = require('superagent');
const NUM_RETRIES = 3;

async function test() {
  let i;
  for (i = 0; i < NUM_RETRIES; ++i) {
    try {
      await superagent.get('http://google.com/this-throws-an-error');
      break;
    } catch(err) {}
  }
  console.log(i); // 3
}

test();
```

上面代码中，如果await操作成功，就会使用break语句退出循环；如果失败，会被catch语句捕捉，然后进入下一轮循环。

使用注意点
第一点，前面已经说过，await命令后面的Promise对象，运行结果可能是rejected，所以最好把await命令放在try...catch代码块中。

```javascript
async function myFunction() {
  try {
    await somethingThatReturnsAPromise();
  } catch (err) {
    console.log(err);
  }
}

// 另一种写法

async function myFunction() {
  await somethingThatReturnsAPromise()
  .catch(function (err) {
    console.log(err);
  });
}
```

第二点，多个await命令后面的异步操作，如果不存在继发关系，最好让它们同时触发。

```javascript
let foo = await getFoo();
let bar = await getBar();
```

上面代码中，getFoo和getBar是两个独立的异步操作（即互不依赖），被写成继发关系。这样比较耗时，因为只有getFoo完成以后，才会执行getBar，完全可以让它们同时触发。

```javascript
// 写法一
let [foo, bar] = await Promise.all([getFoo(), getBar()]);

// 写法二
let fooPromise = getFoo();
let barPromise = getBar();
let foo = await fooPromise;
let bar = await barPromise;
```

上面两种写法，getFoo和getBar都是同时触发，这样就会缩短程序的执行时间。

第三点，await命令只能用在async函数之中，如果用在普通函数，就会报错。

```javascript
async function dbFuc(db) {
  let docs = [{}, {}, {}];

  // 报错
  docs.forEach(function (doc) {
    await db.post(doc);
  });
}
```

上面代码会报错，因为await用在普通函数之中了。但是，如果将forEach方法的参数改成async函数，也有问题。

```javascript
function dbFuc(db) { //这里不需要 async
  let docs = [{}, {}, {}];

  // 可能得到错误结果
  docs.forEach(async function (doc) {
    await db.post(doc);
  });
}
```

上面代码可能不会正常工作，原因是这时三个db.post()操作将是并发执行，也就是同时执行，而不是继发执行。正确的写法是采用for循环。

```javascript
async function dbFuc(db) {
  let docs = [{}, {}, {}];

  for (let doc of docs) {
    await db.post(doc);
  }
}
```

另一种方法是使用数组的reduce()方法。

```javascript
async function dbFuc(db) {
  let docs = [{}, {}, {}];

  await docs.reduce(async (_, doc) => {
    await _;
    await db.post(doc);
  }, undefined);
}
```

上面例子中，reduce()方法的第一个参数是async函数，导致该函数的第一个参数是前一步操作返回的 Promise 对象，所以必须使用await等待它操作结束。另外，reduce()方法返回的是docs数组最后一个成员的async函数的执行结果，也是一个 Promise 对象，导致在它前面也必须加上await。

上面的reduce()的参数函数里面没有return语句，原因是这个函数的主要目的是db.post()操作，不是返回值。而且async函数不管有没有return语句，总是返回一个 Promise 对象，所以这里的return是不必要的。

如果确实希望多个请求并发执行，可以使用Promise.all方法。当三个请求都会resolved时，下面两种写法效果相同。

```javascript
async function dbFuc(db) {
  let docs = [{}, {}, {}];
  let promises = docs.map((doc) => db.post(doc));

  let results = await Promise.all(promises);
  console.log(results);
}

// 或者使用下面的写法

async function dbFuc(db) {
  let docs = [{}, {}, {}];
  let promises = docs.map((doc) => db.post(doc));

  let results = [];
  for (let promise of promises) {
    results.push(await promise);
  }
  console.log(results);
}
```

第四点，async 函数可以保留运行堆栈。

```javascript
const a = () => {
  b().then(() => c());
};
```

上面代码中，函数a内部运行了一个异步任务b()。当b()运行的时候，函数a()不会中断，而是继续执行。等到b()运行结束，可能a()早就运行结束了，b()所在的上下文环境已经消失了。如果b()或c()报错，错误堆栈将不包括a()。

现在将这个例子改成async函数。

```javascript
const a = async () => {
  await b();
  c();
};
```

上面代码中，b()运行的时候，a()是暂停执行，上下文环境都保存着。一旦b()或c()报错，错误堆栈将包括a()。